Traceback (most recent call last):
  File "/opt/hostedtoolcache/Python/3.8.12/x64/lib/python3.8/site-packages/jupyter_cache/executors/utils.py", line 51, in single_nb_execution
    executenb(
  File "/opt/hostedtoolcache/Python/3.8.12/x64/lib/python3.8/site-packages/nbclient/client.py", line 1117, in execute
    return NotebookClient(nb=nb, resources=resources, km=km, **kwargs).execute()
  File "/opt/hostedtoolcache/Python/3.8.12/x64/lib/python3.8/site-packages/nbclient/util.py", line 78, in wrapped
    return just_run(coro(*args, **kwargs))
  File "/opt/hostedtoolcache/Python/3.8.12/x64/lib/python3.8/site-packages/nbclient/util.py", line 57, in just_run
    return loop.run_until_complete(coro)
  File "/opt/hostedtoolcache/Python/3.8.12/x64/lib/python3.8/asyncio/base_events.py", line 616, in run_until_complete
    return future.result()
  File "/opt/hostedtoolcache/Python/3.8.12/x64/lib/python3.8/site-packages/nbclient/client.py", line 558, in async_execute
    await self.async_execute_cell(
  File "/opt/hostedtoolcache/Python/3.8.12/x64/lib/python3.8/site-packages/nbclient/client.py", line 862, in async_execute_cell
    self._check_raise_for_error(cell, exec_reply)
  File "/opt/hostedtoolcache/Python/3.8.12/x64/lib/python3.8/site-packages/nbclient/client.py", line 765, in _check_raise_for_error
    raise CellExecutionError.from_cell_and_msg(cell, exec_reply_content)
nbclient.exceptions.CellExecutionError: An error occurred while executing the following cell:
------------------
from myst_nb import glue
from calitp.tables import tbl
from siuba import _, filter, count, collect, show_query

# query lastest validation notices, then filter for a single gtfs feed,
# and then count how often each code occurs
(tbl.views.validation_notices()
    >> filter(_.calitp_itp_id == 10, _.calitp_url_number==0)
    >> count(_.code)
)
------------------

[0;31m---------------------------------------------------------------------------[0m
[0;31mAttributeError[0m                            Traceback (most recent call last)
[0;32m/tmp/ipykernel_1810/299587592.py[0m in [0;36m<module>[0;34m[0m
[1;32m      5[0m [0;31m# query lastest validation notices, then filter for a single gtfs feed,[0m[0;34m[0m[0;34m[0m[0;34m[0m[0m
[1;32m      6[0m [0;31m# and then count how often each code occurs[0m[0;34m[0m[0;34m[0m[0;34m[0m[0m
[0;32m----> 7[0;31m (tbl.views.validation_notices()
[0m[1;32m      8[0m     [0;34m>>[0m [0mfilter[0m[0;34m([0m[0m_[0m[0;34m.[0m[0mcalitp_itp_id[0m [0;34m==[0m [0;36m10[0m[0;34m,[0m [0m_[0m[0;34m.[0m[0mcalitp_url_number[0m[0;34m==[0m[0;36m0[0m[0;34m)[0m[0;34m[0m[0;34m[0m[0m
[1;32m      9[0m     [0;34m>>[0m [0mcount[0m[0;34m([0m[0m_[0m[0;34m.[0m[0mcode[0m[0;34m)[0m[0;34m[0m[0;34m[0m[0m

[0;32m/opt/hostedtoolcache/Python/3.8.12/x64/lib/python3.8/site-packages/calitp/tables.py[0m in [0;36m__getattr__[0;34m(self, k)[0m
[1;32m     34[0m             [0;32mreturn[0m [0mself[0m[0;34m.[0m[0m_accessors[0m[0;34m[[0m[0mk[0m[0;34m][0m[0;34m[0m[0;34m[0m[0m
[1;32m     35[0m [0;34m[0m[0m
[0;32m---> 36[0;31m         [0;32mraise[0m [0mAttributeError[0m[0;34m([0m[0;34m"No such attribute %s"[0m [0;34m%[0m [0mk[0m[0;34m)[0m[0;34m[0m[0;34m[0m[0m
[0m[1;32m     37[0m [0;34m[0m[0m
[1;32m     38[0m     [0;32mdef[0m [0m__dir__[0m[0;34m([0m[0mself[0m[0;34m)[0m[0;34m:[0m[0;34m[0m[0;34m[0m[0m

[0;31mAttributeError[0m: No such attribute views
AttributeError: No such attribute views

